2020-03-17 16:03:19,562 ERROR: Exception on /user/susan [GET] [in /home/sarthakc/Desktop/microblog/env/lib/python3.8/site-packages/flask/app.py:1890]
Traceback (most recent call last):
  File "/home/sarthakc/Desktop/microblog/env/lib/python3.8/site-packages/flask/app.py", line 2446, in wsgi_app
    response = self.full_dispatch_request()
  File "/home/sarthakc/Desktop/microblog/env/lib/python3.8/site-packages/flask/app.py", line 1951, in full_dispatch_request
    rv = self.handle_user_exception(e)
  File "/home/sarthakc/Desktop/microblog/env/lib/python3.8/site-packages/flask/app.py", line 1820, in handle_user_exception
    reraise(exc_type, exc_value, tb)
  File "/home/sarthakc/Desktop/microblog/env/lib/python3.8/site-packages/flask/_compat.py", line 39, in reraise
    raise value
  File "/home/sarthakc/Desktop/microblog/env/lib/python3.8/site-packages/flask/app.py", line 1949, in full_dispatch_request
    rv = self.dispatch_request()
  File "/home/sarthakc/Desktop/microblog/env/lib/python3.8/site-packages/flask/app.py", line 1935, in dispatch_request
    return self.view_functions[rule.endpoint](**req.view_args)
  File "/home/sarthakc/Desktop/microblog/env/lib/python3.8/site-packages/flask_login/utils.py", line 272, in decorated_view
    return func(*args, **kwargs)
  File "/home/sarthakc/Desktop/microblog/app/routes.py", line 75, in user
    return render_template('user.html',user=user,posts=posts)
  File "/home/sarthakc/Desktop/microblog/env/lib/python3.8/site-packages/flask/templating.py", line 137, in render_template
    return _render(
  File "/home/sarthakc/Desktop/microblog/env/lib/python3.8/site-packages/flask/templating.py", line 120, in _render
    rv = template.render(context)
  File "/home/sarthakc/Desktop/microblog/env/lib/python3.8/site-packages/jinja2/environment.py", line 1090, in render
    self.environment.handle_exception()
  File "/home/sarthakc/Desktop/microblog/env/lib/python3.8/site-packages/jinja2/environment.py", line 832, in handle_exception
    reraise(*rewrite_traceback_stack(source=source))
  File "/home/sarthakc/Desktop/microblog/env/lib/python3.8/site-packages/jinja2/_compat.py", line 28, in reraise
    raise value.with_traceback(tb)
  File "/home/sarthakc/Desktop/microblog/app/templates/user.html", line 1, in top-level template code
    {% extends "base.html" %}
  File "/home/sarthakc/Desktop/microblog/app/templates/base.html", line 32, in top-level template code
    {% block content %}{% endblock %}
  File "/home/sarthakc/Desktop/microblog/app/templates/user.html", line 19, in block "content"
    <p><a href="{{ url_for('unfollow,username=user.username') }}">UNFOLLOW</a></p>
  File "/home/sarthakc/Desktop/microblog/env/lib/python3.8/site-packages/flask/helpers.py", line 370, in url_for
    return appctx.app.handle_url_build_error(error, endpoint, values)
  File "/home/sarthakc/Desktop/microblog/env/lib/python3.8/site-packages/flask/app.py", line 2215, in handle_url_build_error
    reraise(exc_type, exc_value, tb)
  File "/home/sarthakc/Desktop/microblog/env/lib/python3.8/site-packages/flask/_compat.py", line 39, in reraise
    raise value
  File "/home/sarthakc/Desktop/microblog/env/lib/python3.8/site-packages/flask/helpers.py", line 357, in url_for
    rv = url_adapter.build(
  File "/home/sarthakc/Desktop/microblog/env/lib/python3.8/site-packages/werkzeug/routing.py", line 2179, in build
    raise BuildError(endpoint, values, method, self)
werkzeug.routing.BuildError: Could not build url for endpoint 'unfollow,username=user.username'. Did you mean 'unfollow' instead?
2020-03-17 16:04:19,232 ERROR: Exception on /user/susan [GET] [in /home/sarthakc/Desktop/microblog/env/lib/python3.8/site-packages/flask/app.py:1890]
Traceback (most recent call last):
  File "/home/sarthakc/Desktop/microblog/env/lib/python3.8/site-packages/flask/app.py", line 2446, in wsgi_app
    response = self.full_dispatch_request()
  File "/home/sarthakc/Desktop/microblog/env/lib/python3.8/site-packages/flask/app.py", line 1951, in full_dispatch_request
    rv = self.handle_user_exception(e)
  File "/home/sarthakc/Desktop/microblog/env/lib/python3.8/site-packages/flask/app.py", line 1820, in handle_user_exception
    reraise(exc_type, exc_value, tb)
  File "/home/sarthakc/Desktop/microblog/env/lib/python3.8/site-packages/flask/_compat.py", line 39, in reraise
    raise value
  File "/home/sarthakc/Desktop/microblog/env/lib/python3.8/site-packages/flask/app.py", line 1949, in full_dispatch_request
    rv = self.dispatch_request()
  File "/home/sarthakc/Desktop/microblog/env/lib/python3.8/site-packages/flask/app.py", line 1935, in dispatch_request
    return self.view_functions[rule.endpoint](**req.view_args)
  File "/home/sarthakc/Desktop/microblog/env/lib/python3.8/site-packages/flask_login/utils.py", line 272, in decorated_view
    return func(*args, **kwargs)
  File "/home/sarthakc/Desktop/microblog/app/routes.py", line 75, in user
    return render_template('user.html',user=user,posts=posts)
  File "/home/sarthakc/Desktop/microblog/env/lib/python3.8/site-packages/flask/templating.py", line 137, in render_template
    return _render(
  File "/home/sarthakc/Desktop/microblog/env/lib/python3.8/site-packages/flask/templating.py", line 120, in _render
    rv = template.render(context)
  File "/home/sarthakc/Desktop/microblog/env/lib/python3.8/site-packages/jinja2/environment.py", line 1090, in render
    self.environment.handle_exception()
  File "/home/sarthakc/Desktop/microblog/env/lib/python3.8/site-packages/jinja2/environment.py", line 832, in handle_exception
    reraise(*rewrite_traceback_stack(source=source))
  File "/home/sarthakc/Desktop/microblog/env/lib/python3.8/site-packages/jinja2/_compat.py", line 28, in reraise
    raise value.with_traceback(tb)
  File "/home/sarthakc/Desktop/microblog/app/templates/user.html", line 1, in top-level template code
    {% extends "base.html" %}
  File "/home/sarthakc/Desktop/microblog/app/templates/base.html", line 32, in top-level template code
    {% block content %}{% endblock %}
  File "/home/sarthakc/Desktop/microblog/app/templates/user.html", line 19, in block "content"
    <p><a href="{{ url_for('unfollow',username=user.username') }}">UNFOLLOW</a></p>
  File "/home/sarthakc/Desktop/microblog/env/lib/python3.8/site-packages/flask/helpers.py", line 370, in url_for
    return appctx.app.handle_url_build_error(error, endpoint, values)
  File "/home/sarthakc/Desktop/microblog/env/lib/python3.8/site-packages/flask/app.py", line 2215, in handle_url_build_error
    reraise(exc_type, exc_value, tb)
  File "/home/sarthakc/Desktop/microblog/env/lib/python3.8/site-packages/flask/_compat.py", line 39, in reraise
    raise value
  File "/home/sarthakc/Desktop/microblog/env/lib/python3.8/site-packages/flask/helpers.py", line 357, in url_for
    rv = url_adapter.build(
  File "/home/sarthakc/Desktop/microblog/env/lib/python3.8/site-packages/werkzeug/routing.py", line 2179, in build
    raise BuildError(endpoint, values, method, self)
werkzeug.routing.BuildError: Could not build url for endpoint 'unfollow,username=user.username'. Did you mean 'unfollow' instead?
